Workbook

Sheet Análisis
A1: Análisis integral · 29 dic 2025 – 10 may 2026 · 19 semanas
A3: RESUMEN EJECUTIVO
A4: En 19 semanas IMCO sumó ~10,679 seguidores netos en las 5 redes principales y acumuló ~6 millones de impresiones. Instagram y TikTok lideran el crecimiento porcentual (+24.3% y +31.9%); Twitter es el más comprometido (ER 6.68%) pero su crecimiento de seguidores está estancado (+0.6%). En proyección lineal, 4 de 5 metas anuales de seguidores se cumplirán; solo TikTok va rezagado. Las metas de alcance ya están superadas excepto Twitter (96%). El newsletter muestra una caída sostenida y estadísticamente significativa en la tasa de apertura (-7 pp desde enero). YouTube es volátil: 46% de las vistas se concentra en 3 semanas.
A6: REDES SOCIALES — VISIÓN GENERAL
A7: Plataforma | B7: Inicio | C7: Fin | D7: Crecimiento | E7: % crec. | F7: ER prom.
A8: Facebook | B8: 135,044 | C8: 138,225 | D8: +3,181 | E8: +2.4% | F8: 2.17%
A9: Twitter/X | B9: 145,071 | C9: 145,896 | D9: +825 | E9: +0.6% | F9: 6.68%
A10: Instagram | B10: 14,409 | C10: 17,904 | D10: +3,495 | E10: +24.3% | F10: 2.51%
A11: LinkedIn | B11: 21,760 | C11: 23,954 | D11: +2,194 | E11: +10.1% | F11: 1.86%
A12: TikTok | B12: 3,089 | C12: 4,073 | D12: +984 | E12: +31.9% | F12: 5.71%
A14: Hallazgos clave por plataforma
A15: Facebook | B15: Volumen líder en impresiones (2.5M acumuladas) pero crecimiento estancado (+2.4%). Volatilidad alta (CV 75%): la semana pico tuvo 14x más impresiones que la peor. Mediana (93k) muy por debajo del promedio (132k): pocos posts dominan el alcance.
A16: Twitter/X | B16: Mejor ER del portafolio (6.68%) — la audiencia más comprometida. Pero crecimiento casi nulo (+41 seguidores/semana). La meta anual de +1,800 va al 46% con el año al 35%: se cumplirá apenas.
A17: Instagram | B17: Estrella en crecimiento absoluto (+3,495, +24.3%). Volatilidad altísima (CV 191%) por la semana pico de 583k. Meta anual ya al 57% del año transcurrido al 35% — va adelantada.
A18: LinkedIn | B18: Crecimiento moderado (+10.1%) consistente con el perfil B2B. ER bajo (1.86%) pero esperable para la plataforma. El ICR 2026 disparó el alcance en su semana de lanzamiento.
A19: TikTok | B19: Mayor crecimiento porcentual (+31.9%) sobre base pequeña. En proyección lineal NO alcanza la meta anual: necesita +57.7 seguidores/semana, va a +52.
A21: PROGRESO HACIA METAS ANUALES 2026
A22: Al 10 de mayo se transcurrió el 35% del año. Proyección lineal del ritmo actual:
A23: Plataforma | B23: Crec/sem | C23: Proy. fin 2026 | D23: Meta fin 2026 | E23: ¿Cumple?
A24: Facebook | B24: +167 | C24: 143,750 | D24: 138,824 | E24: Sí — holgado
A25: Twitter/X | B25: +43 | C25: 147,329 | D25: 146,871 | E25: Sí — apenas
A26: Instagram | B26: +184 | C26: 23,974 | D26: 20,529 | E26: Sí — holgado
A27: LinkedIn | B27: +115 | C27: 27,765 | D27: 26,260 | E27: Sí — holgado
A28: TikTok | B28: +52 | C28: 5,782 | D28: 6,089 | E28: No — falta 5%
A30: ALCANCE: REAL vs META MENSUAL
A31: Impresiones acumuladas en 19 semanas (≈4.33 meses) contra meta proporcional:
A32: Plataforma | B32: 19 semanas | C32: Meta mensual | D32: Meta acum. | E32: % logro
A33: Facebook | B33: 2,503,237 | C33: 350,000 | D33: 1,515,800 | E33: 165%
A34: Twitter/X | B34: 1,470,522 | C34: 350,000 | D34: 1,515,800 | E34: 97%
A35: Instagram | B35: 1,267,932 | C35: 150,000 | D35: 649,650 | E35: 195%
A36: LinkedIn | B36: 545,656 | C36: 85,000 | D36: 368,050 | E36: 148%
A37: TikTok | B37: 235,473 | C37: 45,000 | D37: 194,850 | E37: 121%
A39: Twitter es la única plataforma corta vs meta de alcance (-45k impresiones). Las demás están 21% a 95% por encima.
A41: POSICIONAMIENTO vs OTROS THINK TANKS
A42: Crecimiento de seguidores entre 20 ene y 30 mar (≈10 semanas):
A43: Twitter/X
A44: Think tank | B44: 20 ene | C44: 30 mar | D44: Cambio | E44: %
A45: Mexicanos contra la corrupción | B45: 396,242 | C45: 398,507 | D45: +2,265 | E45: +0.57%
A46: IMCO | B46: 145,189 | C46: 145,589 | D46: +400 | E46: +0.28%
A47: Data Cívica | B47: 33,144 | C47: 33,190 | D47: +46 | E47: +0.14%
...

Sheet Reporte semanal 2026
B1: 29 de diciembre al 4 de enero | C1: Diferencia | D1: 5 de enero al 11 de enero | E1: Diferencia | F1: 12 de enero al 18 de enero | G1: Diferencia | H1: 19 de enero al 25 de enero | I1: Diferencia | J1: 26 de enero al 1 de febrero | K1: Diferencia | L1: 2 de febrero al 8 de febrero | M1: Diferencia | N1: 9 de febrero al 15 de febrero | O1: Diferencia | P1: 16 de febrero al 22 de febrero | Q1: Diferencia | R1: 23 de febrero al 1 de marzo | S1: Diferencia | T1: 2 de marzo al 8 de marzo | U1: Diferencia | V1: 9 de marzo al 15 de marzo | W1: Diferencia | X1: 16 de marzo al 22 de marzo | Y1: Diferencia | Z1: 23 de marzo al 29 de marzo | AA1: Diferencia | AB1: 30 de marzo al 5 de abril | AC1: Diferencia | AD1: 6 de abril al 12 de abril | AE1: Diferencia | AF1: 13 de abril al 19 de abril | AG1: Diferencia | AH1: 20 al 26 de abril | AJ1: 27 de abril al 3 de mayo | AK1: Diferencia | AL1: 4 al 10 de mayo | AM1: Diferencia
A2: Facebook
A3: Núm de seguidores | B3: 135044 | C3: 249 | D3: 135168 | E3: =D3-B3 | F3: 135217 | G3: =F3-D3 | H3: 135588 | I3: =H3-F3 | J3: 135812 | K3: =J3-H3 | L3: 135863 | M3: =L3-J3 | N3: 136063 | O3: =N3-L3 | P3: 136180 | Q3: =P3-N3 | R3: 136255 | S3: =R3-P3 | T3: 136653 | U3: =T3-R3 | V3: 136725 | W3: =V3-T3 | X3: 136950 | Y3: =X3-V3 | Z3: 137686 | AA3: =Z3-X3 | AB3: 137734 | AC3: =AB3-Z3 | AD3: 137784 | AE3: =AD3-AB3 | AF3: 137822 | AG3: =AF3-AD3 | AH3: 137793 | AI3: =AH3-AF3 | AJ3: 137821 | AK3: =AJ3-AH3 | AL3: 138225 | AM3: =AL3-AJ3
A4: Impresiones (views) | B4: 125807 | C4: -65182 | D4: 91614 | E4: =D4-B4 | F4: 41882 | G4: =F4-D4 | H4: 238168 | I4: =H4-F4 | J4: 80697 | K4: =J4-H4 | L4: 55740 | M4: =L4-J4 | N4: 127520 | O4: =N4-L4 | P4: 93163 | Q4: =P4-N4 | R4: 124223 | S4: =R4-P4 | T4: 353056 | U4: =T4-R4 | V4: 93926 | W4: =V4-T4 | X4: 201646 | Y4: =X4-V4 | Z4: 264288 | AA4: =Z4-X4 | AB4: 57131 | AC4: =AB4-Z4 | AD4: 79850 | AE4: =AD4-AB4 | AF4: 77429 | AG4: =AF4-AD4 | AH4: 25010 | AI4: =AH4-AF4 | AJ4: 40884 | AK4: =AJ4-AH4 | AL4: 331203 | AM4: =AL4-AJ4
A5: Interacciones (Reactions, comments and shares) | B5: 1381 | C5: -549 | D5: 1734 | E5: =D5-B5 | F5: 942 | G5: =F5-D5 | H5: 4466 | I5: =H5-F5 | J5: 1730 | K5: =J5-H5 | L5: 1220 | M5: =L5-J5 | N5: 2853 | O5: =N5-L5 | P5: 1908 | Q5: =P5-N5 | R5: 2329 | S5: =R5-P5 | T5: 9247 | U5: =T5-R5 | V5: 2359 | W5: =V5-T5 | X5: 3889 | Y5: =X5-V5 | Z5: 5556 | AA5: =Z5-X5 | AB5: 1544 | AC5: =AB5-Z5 | AD5: 1954 | AE5: =AD5-AB5 | AF5: 1842 | AG5: =AF5-AD5 | AH5: 433 | AI5: =AH5-AF5 | AJ5: 963 | AK5: =AJ5-AH5 | AL5: 7851 | AM5: =AL5-AJ5
A6: Engagement rate (rango de entre 3% y 5%) | B6: =B5/B4 | D6: =D5/D4 | F6: =F5/F4 | H6: =H5/H4 | J6: =J5/J4 | L6: =L5/L4 | N6: =N5/N4 | P6: =P5/P4 | R6: =R5/R4 | T6: =T5/T4 | V6: =V5/V4 | X6: =X5/X4 | Z6: =Z5/Z4 | AB6: =AB5/AB4 | AD6: =AD5/AD4 | AF6: =AF5/AF4 | AH6: =AH5/AH4 | AJ6: =AJ5/AJ4 | AL6: =AL5/AL4
A7: Twitter
A8: Followers totales | B8: 145071 | C8: 41 | D8: 145148 | E8: =D8-B8 | F8: 145164 | G8: =F8-D8 | H8: 145202 | I8: =H8-F8 | J8: 145194 | K8: =J8-H8 | L8: 145220 | M8: =L8-J8 | N8: 145238 | O8: =N8-L8 | P8: 145281 | Q8: =P8-N8 | R8: 145319 | S8: =R8-P8 | T8: 145433 | U8: =T8-R8 | V8: 145448 | W8: =V8-T8 | X8: 145555 | Y8: =X8-V8 | Z8: 145652 | AA8: =Z8-X8 | AB8: 145588 | AC8: =AB8-Z8 | AD8: 145429 | AE8: =AD8-AB8 | AF8: 145622 | AG8: =AF8-AD8 | AH8: 145762 | AI8: =AH8-AF8 | AJ8: 145761 | AK8: =AJ8-AH8 | AL8: 145896 | AM8: =AL8-AJ8
A9: Impresiones | B9: 49544 | C9: 10734 | D9: 46674 | E9: =D9-B9 | F9: 93643 | G9: =F9-D9 | H9: 96158 | I9: =H9-F9 | J9: 61328 | K9: =J9-H9 | L9: 43309 | M9: =L9-J9 | N9: 32979 | O9: =N9-L9 | P9: 41114 | Q9: =P9-N9 | R9: 68041 | S9: =R9-P9 | T9: 109402 | U9: =T9-R9 | V9: 42066 | W9: =V9-T9 | X9: 184851 | Y9: =X9-V9 | Z9: 108050 | AA9: =Z9-X9 | AB9: 49993 | AC9: =AB9-Z9 | AD9: 44739 | AE9: =AD9-AB9 | AF9: 47285 | AG9: =AF9-AD9 | AH9: 57772 | AI9: =AH9-AF9 | AJ9: 48530 | AK9: =AJ9-AH9 | AL9: 245044 | AM9: =AL9-AJ9
A10: Interacciones (Likes, shares and follows) | B10: 5393 | C10: 2282 | D10: 4648 | E10: =D10-B10 | F10: 3967 | G10: =F10-D10 | H10: 4103 | I10: =H10-F10 | J10: 4460 | K10: =J10-H10 | L10: 3500 | M10: =L10-J10 | N10: 2915 | O10: =N10-L10 | P10: 3491 | Q10: =P10-N10 | R10: 4941 | S10: =R10-P10 | T10: 8284 | U10: =T10-R10 | V10: 2857 | W10: =V10-T10 | X10: 9737 | Y10: =X10-V10 | Z10: 6540 | AA10: =Z10-X10 | AB10: 3614 | AC10: =AB10-Z10 | AD10: 3995 | AE10: =AD10-AB10 | AF10: 4697 | AG10: =AF10-AD10 | AH10: 4269 | AI10: =AH10-AF10 | AJ10: 2525 | AK10: =AJ10-AH10 | AL10: 14258 | AM10: =AL10-AJ10
A11: Engagement rate (rango de entre 3% y 5%) | B11: =B10/B9 | D11: =D10/D9 | F11: =F10/F9 | H11: =H10/H9 | J11: =J10/J9 | L11: =L10/L9 | N11: =N10/N9 | P11: =P10/P9 | R11: =R10/R9 | T11: =T10/T9 | V11: =V10/V9 | X11: =X10/X9 | Z11: =Z10/Z9 | AB11: =AB10/AB9 | AD11: =AD10/AD9 | AF11: =AF10/AF9 | AH11: =AH10/AH9 | AJ11: =AJ10/AJ9 | AL11: =AL10/AL9
A12: Instagram
A13: Número de followers | B13: 14409 | C13: 35 | D13: 14710 | E13: =D13-B13 | F13: 14875 | G13: =F13-D13 | H13: 14969 | I13: =H13-F13 | J13: 15056 | K13: =J13-H13 | L13: 15150 | M13: =L13-J13 | N13: 15270 | O13: =N13-L13 | P13: 15361 | Q13: =P13-N13 | R13: 15486 | S13: =R13-P13 | T13: 16445 | U13: =T13-R13 | V13: 16516 | W13: =V13-T13 | X13: 16842 | Y13: =X13-V13 | Z13: 17241 | AA13: =Z13-X13 | AB13: 17385 | AC13: =AB13-Z13 | AD13: 17513 | AE13: =AD13-AB13 | AF13: 17573 | AG13: =AF13-AD13 | AH13: 17623 | AI13: =AH13-AF13 | AJ13: 17707 | AK13: =AJ13-AH13 | AL13: 17904 | AM13: =AL13-AJ13
A14: Impresiones (views) | B14: 10748 | C14: -48102 | D14: 42403 | E14: =D14-B14 | F14: 19891 | G14: =F14-D14 | H14: 18656 | I14: =H14-F14 | J14: 25455 | K14: =J14-H14 | L14: 28393 | M14: =L14-J14 | N14: 40103 | O14: =N14-L14 | P14: 31788 | Q14: =P14-N14 | R14: 42293 | S14: =R14-P14 | T14: 583905 | U14: =T14-R14 | V14: 42066 | W14: =V14-T14 | X14: 38725 | Y14: =X14-V14 | Z14: 66299 | AA14: =Z14-X14 | AB14: 33696 | AC14: =AB14-Z14 | AD14: 36622 | AE14: =AD14-AB14 | AF14: 28699 | AG14: =AF14-AD14 | AH14: 26288 | AI14: =AH14-AF14 | AJ14: 33424 | AK14: =AJ14-AH14 | AL14: 118478 | AM14: =AL14-AJ14
A15: Reel (views) | B15: 2966 | C15: -2177 | D15: 13674 | E15: =D15-B15 | F15: 6744 | G15: =F15-D15 | H15: 8399 | I15: =H15-F15 | J15: 11963 | K15: =J15-H15 | L15: 10950 | M15: =L15-J15 | N15: 916 | O15: =N15-L15 | P15: 12008 | Q15: =P15-N15 | R15: 4924 | S15: =R15-P15 | T15: 29757 | U15: =T15-R15 | V15: 7703 | W15: =V15-T15 | X15: 11158 | Y15: =X15-V15 | Z15: 54522 | AA15: =Z15-X15 | AB15: 5039 | AC15: =AB15-Z15 | AD15: 20557 | AE15: =AD15-AB15 | AF15: 13455 | AG15: =AF15-AD15 | AH15: 12157 | AI15: =AH15-AF15 | AK15: =AJ15-AH15 | AL15: 24662 | AM15: =AL15-AJ15
A16: Interacciones totales (likes) | B16: 250 | C16: -435 | D16: 1281 | E16: =D16-B16 | F16: 568 | G16: =F16-D16 | H16: 378 | I16: =H16-F16 | J16: 711 | K16: =J16-H16 | L16: 682 | M16: =L16-J16 | N16: 980 | O16: =N16-L16 | P16: 876 | Q16: =P16-N16 | R16: 682 | S16: =R16-P16 | T16: 12688 | U16: =T16-R16 | V16: 1356 | W16: =V16-T16 | X16: 978 | Y16: =X16-V16 | Z16: 2459 | AA16: =Z16-X16 | AB16: 890 | AC16: =AB16-Z16 | AD16: 1259 | AE16: =AD16-AB16 | AF16: 651 | AG16: =AF16-AD16 | AH16: 675 | AI16: =AH16-AF16 | AJ16: 1120 | AK16: =AJ16-AH16 | AL16: 3394 | AM16: =AL16-AJ16
A17: Engagement rate (rango de entre 3% y 5%) | B17: =(B16/B14)*100 | D17: =(D16/D14)*100 | F17: =(F16/F14)*100 | H17: =(H16/H14)*100 | J17: =(J16/J14)*100 | L17: =(L16/L14)*100 | N17: =(N16/N14)*100 | P17: =(P16/P14)*100 | R17: =(R16/R14)*100 | T17: =(T16/T14)*100 | V17: =(V16/V14)*100 | X17: =(X16/X14)*100 | Z17: =(Z16/Z14)*100 | AB17: =(AB16/AB14)*100 | AD17: =(AD16/AD14)*100 | AF17: =(AF16/AF14)*100 | AH17: =(AH16/AH14)*100 | AJ17: =(AJ16/AJ14) | AL17: =(AL16/AL14)
A18: LinkedIn
A19: Total de seguidores | B19: 21760 | C19: 107 | D19: 21888 | E19: =D19-B19 | F19: 21978 | G19: =F19-D19 | H19: 22032 | I19: =H19-F19 | J19: 22094 | K19: =J19-H19 | L19: 22156 | M19: =L19-J19 | N19: 22233 | O19: =N19-L19 | P19: 22301 | Q19: =P19-N19 | R19: 22435 | S19: =R19-P19 | T19: 22682 | U19: =T19-R19 | V19: 22820 | W19: =V19-T19 | X19: 23042 | Y19: =X19-V19 | Z19: 23173 | AA19: =Z19-X19 | AB19: 23323 | AC19: =AB19-Z19 | AD19: 23445 | AE19: =AD19-AB19 | AF19: 23555 | AG19: =AF19-AD19 | AH19: 23675 | AI19: =AH19-AF19 | AJ19: 23788 | AK19: =AJ19-AH19 | AL19: 23954 | AM19: =AL19-AJ19
A20: Impresiones totales | B20: 25464 | C20: 14265 | D20: 35697 | E20: =D20-B20 | F20: 13956 | G20: =F20-D20 | H20: 16759 | I20: =H20-F20 | J20: 16835 | K20: =J20-H20 | L20: 12224 | M20: =L20-J20 | N20: 21713 | O20: =N20-L20 | P20: 18812 | Q20: =P20-N20 | R20: 106703 | S20: =R20-P20 | T20: 46766 | U20: =T20-R20 | V20: 38220 | W20: =V20-T20 | X20: 23526 | Y20: =X20-V20 | Z20: 26014 | AA20: =Z20-X20 | AB20: 30872 | AC20: =AB20-Z20 | AD20: 27924 | AE20: =AD20-AB20 | AF20: 18843 | AG20: =AF20-AD20 | AH20: 25546 | AI20: =AH20-AF20 | AJ20: 10287 | AK20: =AJ20-AH20 | AL20: 29495 | AM20: =AL20-AJ20
A21: Reacciones totales | B21: 365 | C21: 209 | D21: 494 | E21: =D21-B21 | F21: 239 | G21: =F21-D21 | H21: 270 | I21: =H21-F21 | J21: 245 | K21: =J21-H21 | L21: 227 | M21: =L21-J21 | N21: 557 | O21: =N21-L21 | P21: 361 | Q21: =P21-N21 | R21: 1809 | S21: =R21-P21 | T21: 1004 | U21: =T21-R21 | V21: 803 | W21: =V21-T21 | X21: 435 | Y21: =X21-V21 | Z21: 508 | AA21: =Z21-X21 | AB21: 652 | AC21: =AB21-Z21 | AD21: 370 | AE21: =AD21-AB21 | AF21: 286 | AG21: =AF21-AD21 | AH21: 448 | AI21: =AH21-AF21 | AJ21: 344 | AK21: =AJ21-AH21 | AL21: 747 | AM21: =AL21-AJ21
A22: Engagement rate (rango de entre 3% y 5%) | B22: =B21/B20 | D22: =D21/D20 | F22: =F21/F20 | H22: =H21/H20 | J22: =J21/J20 | L22: =L21/L20 | N22: =N21/N20 | P22: =P21/P20 | R22: =R21/R20 | T22: =T21/T20 | V22: =V21/V20 | X22: =X21/X20 | Z22: =Z21/Z20 | AB22: =AB21/AB20 | AD22: =AD21/AD20 | AF22: =AF21/AF20 | AH22: =AH21/AH20 | AJ22: =AJ21/AJ20 | AL22: =AL21/AL20
A23: TikTok
A24: Número de seguidores | B24: 3089 | C24: 17 | D24: 3111 | E24: =D24-B24 | F24: 3117 | G24: =F24-D24 | H24: 3127 | I24: =H24-F24 | J24: 3324 | K24: =J24-H24 | L24: 3362 | M24: =L24-J24 | N24: 3384 | O24: =N24-L24 | P24: 3401 | Q24: =P24-N24 | R24: 3412 | S24: =R24-P24 | T24: 3594 | U24: =T24-R24 | V24: 3603 | W24: =V24-T24 | X24: 3625 | Y24: =X24-V24 | Z24: 3908 | AA24: =Z24-X24 | AB24: 3936 | AC24: =AB24-Z24 | AD24: 3992 | AE24: =AD24-AB24 | AF24: 4013 | AG24: =AF24-AD24 | AH24: 4034 | AI24: =AH24-AF24 | AJ24: 4068 | AK24: =AJ24-AH24 | AL24: 4073 | AM24: =AL24-AJ24
A25: Visualizaciones | B25: 5457 | C25: -235 | D25: 5579 | E25: =D25-B25 | F25: 5397 | G25: =F25-D25 | H25: 7832 | I25: =H25-F25 | J25: 10712 | K25: =J25-H25 | L25: 11672 | M25: =L25-J25 | N25: 4076 | O25: =N25-L25 | P25: 8178 | Q25: =P25-N25 | R25: 6396 | S25: =R25-P25 | T25: 55803 | U25: =T25-R25 | V25: 11407 | W25: =V25-T25 | X25: 6286 | Y25: =X25-V25 | Z25: 35906 | AA25: =Z25-X25 | AB25: 24639 | AC25: =AB25-Z25 | AD25: 11763 | AE25: =AD25-AB25 | AF25: 7990 | AG25: =AF25-AD25 | AH25: 4742 | AI25: =AH25-AF25 | AJ25: 6913 | AK25: =AJ25-AH25 | AL25: 4725 | AM25: =AL25-AJ25
A26: Me gusta | B26: 157 | C26: -10 | D26: 138 | E26: =D26-B26 | F26: 140 | G26: =F26-D26 | H26: 186 | I26: =H26-F26 | J26: 397 | K26: =J26-H26 | L26: 402 | M26: =L26-J26 | N26: 114 | O26: =N26-L26 | P26: 305 | Q26: =P26-N26 | R26: 195 | S26: =R26-P26 | T26: 7084 | U26: =T26-R26 | V26: 632 | W26: =V26-T26 | X26: 152 | Y26: =X26-V26 | Z26: 1273 | AA26: =Z26-X26 | AB26: 709 | AC26: =AB26-Z26 | AD26: 409 | AE26: =AD26-AB26 | AF26: 497 | AG26: =AF26-AD26 | AH26: 260 | AI26: =AH26-AF26 | AJ26: 264 | AK26: =AJ26-AH26 | AL26: 131 | AM26: =AL26-AJ26
A27: Engagement rate (rango de entre 3% y 5%) | B27: =B26/B25 | D27: =D26/D25 | F27: =F26/F25 | H27: =H26/H25 | J27: =J26/J25 | L27: =L26/L25 | N27: =N26/N25 | P27: =P26/P25 | R27: =R26/R25 | T27: =T26/T25 | V27: =V26/V25 | X27: =X26/X25 | Z27: =Z26/Z25 | AB27: =AB26/AB25 | AD27: =AD26/AD25 | AF27: =AF26/AF25 | AH27: =AH26/AH25 | AJ27: =AJ26/AJ25 | AL27: =AL26/AL25
A28: Youtube
A29: Suscriptores | B29: 2 | D29: 0 | E29: -2 | F29: 1 | G29: 1 | H29: 7 | I29: 6 | J29: 14 | K29: 7 | L29: 3 | M29: -11 | N29: 8 | O29: 5 | P29: 5 | Q29: -3 | R29: 6 | S29: 1 | T29: 2 | U29: -4 | V29: 8 | W29: 6 | X29: 8 | Y29: 0 | Z29: 16 | AA29: 8 | AB29: 16 | AC29: 0 | AD29: 14 | AE29: -2 | AF29: 4 | AG29: -10 | AH29: 1 | AI29: -3 | AJ29: 3 | AK29: 2 | AL29: 6 | AM29: 3
A30: Tiempo de reproducción / horas | B30: 8.4 | D30: 8.8 | E30: 0.4 | F30: 15.7 | G30: 6.9 | H30: 21.8 | I30: 6.1 | J30: 81.3 | K30: 59.5 | L30: 13.9 | M30: -67.4 | N30: 66.4 | O30: 52.5 | P30: 37.3 | Q30: -29.1 | R30: 10.8 | S30: -26.5 | T30: 14.3 | U30: 3.5 | V30: 66.6 | W30: 52.3 | X30: 45.1 | Y30: -21.5 | Z30: 217.1 | AA30: 172 | AB30: 61.2 | AC30: -155.9 | AD30: 51.3 | AE30: -9.9 | AF30: 26.5 | AG30: -24.8 | AH30: 15.6 | AI30: -10.9 | AJ30: 17.5 | AK30: 1.9 | AL30: 16.9 | AM30: -0.6
A31: Vistas | B31: 846 | C31: -1009 | D31: 878 | E31: 32 | F31: 3179 | G31: 2301 | H31: 1548 | I31: -1631 | J31: 1131 | K31: -417 | L31: 9276 | M31: 8145 | N31: 4422 | O31: -4854 | P31: 1061 | Q31: -3361 | R31: 1408 | S31: 347 | T31: 8209 | U31: 6801 | V31: 2541 | W31: -5668 | X31: 9481 | Y31: 6940 | Z31: 15092 | AA31: 5611 | AB31: 6555 | AC31: -8537 | AD31: 2890 | AE31: -3665 | AF31: 1075 | AG31: -1815 | AH31: 1003 | AI31: -72 | AJ31: 2430 | AK31: 1427 | AL31: 575 | AM31: -1855
A32: Newsletter
A33: Entregados | D33: 14037 | F33: 14031 | G33: -6 | H33: 13344 | I33: -687 | J33: 12613 | K33: -731 | L33: 12509 | M33: -104 | N33: 13149 | O33: 640 | P33: 12442 | Q33: -707 | R33: 13816 | S33: 1374 | T33: 13986 | U33: 170 | V33: 13791 | W33: -195 | X33: 13748 | Y33: -43 | Z33: 13734 | AA33: -14 | AB33: 13701 | AC33: -33 | AD33: 13688 | AE33: -13 | AF33: 13669 | AG33: -19 | AH33: 13663 | AI33: -6 | AJ33: 13731 | AK33: 68 | AL33: 13707 | AM33: -24
A34: Apertura | D34: 4499 | F34: 4239 | G34: -260 | H34: 4036 | I34: -203 | J34: 3729 | K34: -307 | L34: 3944 | M34: 215 | N34: 3931 | O34: -13 | P34: 3845 | Q34: -86 | R34: 4162 | S34: 317 | T34: 4060 | U34: -102 | V34: 3960 | W34: -100 | X34: 3818 | Y34: -142 | Z34: 3839 | AA34: 21 | AB34: 3657 | AC34: -182 | AD34: 3858 | AE34: 201 | AF34: 3775 | AG34: -83 | AH34: 3725 | AI34: -50 | AJ34: 3583 | AK34: -142 | AL34: 3448 | AM34: -135
A35: Clics | D35: 276 | F35: 150 | G35: -126 | H35: 169 | I35: 19 | J35: 167 | K35: -2 | L35: 145 | M35: -22 | N35: 126 | O35: -19 | P35: 116 | Q35: -10 | R35: 166 | S35: 50 | T35: 171 | U35: 5 | V35: 199 | W35: 28 | X35: 147 | Y35: -52 | Z35: 163 | AA35: 16 | AB35: 173 | AC35: 10 | AD35: 180 | AE35: 7 | AF35: 173 | AG35: -7 | AH35: 140 | AI35: -33 | AJ35: 167 | AK35: 27 | AL35: 150 | AM35: -17

Sheet Nuevo reporte
B1: ORIGINAL | O1: ↑ | P1: ↓
C2: Seguidores Totales | D2: Crecimiento de nuevos seguidores | E2: Alcance | G2: Engagement | L2: Seguidores | O2: Alcance | R2: Engagement
B3: Facebook | C3: 137821 | D3: 28 | E3: 40884 | F3: ↑ | G3: 0.023554447 | H3: ↑ | J3: ↑ | L3: Actual | M3: Pasada | N3: Var | O3: Actual | P3: Pasada | Q3: Var | R3: Actual | S3: Pasada | T3: Var
B4: Twitter | C4: 145761 | D4: -1 | E4: 48530 | F4: ↓ | G4: 0.052029672 | H4: ↓ | J4: ↓ | K4: Facebook | L4: ='Reporte semanal 2026'!AL3 | M4: 137821 | N4: =L4-M4 | O4: ='Reporte semanal 2026'!AL4 | P4: 40884 | Q4: =O4-P4 | R4: ='Reporte semanal 2026'!AL6 | S4: 0.023554447 | T4: =R4-S4
B5: Instagram | C5: 17707 | D5: 84 | E5: 33424 | F5: ↑ | G5: 0.033508856 | H5: ↑ | K5: Twitter | L5: ='Reporte semanal 2026'!AL8 | M5: 145761 | N5: =L5-M5 | O5: ='Reporte semanal 2026'!AL9 | P5: 48530 | Q5: =O5-P5 | R5: ='Reporte semanal 2026'!AL11 | S5: 0.052029672 | T5: =R5-S5
B6: LinkedIn | C6: 23788 | D6: 113 | E6: 10287 | F6: ↓ | G6: 0.033440264 | H6: ↑ | K6: Instagram | L6: ='Reporte semanal 2026'!AL13 | M6: 17707 | N6: =L6-M6 | O6: ='Reporte semanal 2026'!AL14 | P6: 33424 | Q6: =O6-P6 | R6: ='Reporte semanal 2026'!AL17 | S6: 0.033508856 | T6: =R6-S6
B7: Tiktok | C7: 4068 | D7: 34 | E7: 6913 | F7: ↑ | G7: 0.038188919 | H7: ↓ | K7: LinkedIn | L7: ='Reporte semanal 2026'!AL19 | M7: 23788 | N7: =L7-M7 | O7: ='Reporte semanal 2026'!AL20 | P7: 10287 | Q7: =O7-P7 | R7: ='Reporte semanal 2026'!AL22 | S7: 0.033440264 | T7: =R7-S7
K8: Tiktok | L8: ='Reporte semanal 2026'!AL24 | M8: 4068 | N8: =L8-M8 | O8: ='Reporte semanal 2026'!AL25 | P8: 6913 | Q8: =O8-P8 | R8: ='Reporte semanal 2026'!AL27 | S8: 0.038188919 | T8: =R8-S8
B9: CAPTURA
K10: FORMULADA
C11: Seguidores Totales | D11: Crecimiento de nuevos seguidores | E11: Alcance | G11: Engagement | L11: Seguidores Totales | M11: Crecimiento de nuevos seguidores | N11: Alcance | P11: Engagement
B12: Facebook | C12: 138225 | D12: 404 | E12: 331203 | F12: ↑ | G12: 0.023704495 | H12: ↑ | K12: Facebook | L12: =L4 | M12: =N4 | N12: =O4 | O12: =Q4 | P12: =R4 | Q12: =T4
B13: Twitter | C13: 145896 | D13: 135 | E13: 245044 | F13: ↑ | G13: 0.058185469 | H13: ↑ | K13: Twitter | L13: =L5 | M13: =N5 | N13: =O5 | O13: =Q5 | P13: =R5 | Q13: =T5
B14: Instagram | C14: 17904 | D14: 197 | E14: 118478 | F14: ↑ | G14: 0.028646669 | H14: ↓ | K14: Instagram | L14: =L6 | M14: =N6 | N14: =O6 | O14: =Q6 | P14: =R6 | Q14: =T6
B15: LinkedIn | C15: 23954 | D15: 166 | E15: 29495 | F15: ↑ | G15: 0.025326326 | H15: ↓ | K15: LinkedIn | L15: =L7 | M15: =N7 | N15: =O7 | O15: =Q7 | P15: =R7 | Q15: =T7
B16: Tiktok | C16: 4073 | D16: 5 | E16: 4725 | F16: ↓ | G16: 0.027724868 | H16: ↓ | K16: Tiktok | L16: =L8 | M16: =N8 | N16: =O8 | O16: =Q8 | P16: =R8 | Q16: =T8

Sheet Reporte mensual 2026
B1: Enero | C1: Febrero | D1: Marzo | E1: Abril | F1: Mayo | G1: Junio | H1: Julio | I1: Agosto | J1: Septiembre | K1: Octubre | L1: Noviembre | M1: Diciembre
A2: Facebook
A3: Núm de seguidores | B3: 135812 | C3: 136255 | D3: 137734
A4: Impresiones | B4: 591045 | C4: 449232 | D4: 1072767
A5: Interacciones (Reactions, comments and shares) | B5: 10488 | C5: 8929 | D5: 23942
A6: Engagement rate (rango de entre 3% y 5%) | B6: =B5/B4 | C6: =C5/C4 | D6: =D5/D4
A7: Twitter
A8: Followers totales | B8: 145194 | C8: 145319 | D8: 145588
A9: Impresiones | B9: 333491 | C9: 198556 | D9: 493938
A10: Interacciones (Likes, shares and follows) | B10: 25328 | C10: 15880 | D10: 29734
A11: Engagement rate (rango de entre 3% y 5%) | B11: =B10/B9 | C11: =C10/C9 | D11: =D10/D9
A12: Instagram
A13: Número de followers | B13: 15056 | C13: 15486 | D13: 17385
A14: Impresiones (views) | B14: 122452 | C14: 167904 | D14: 864800
A15: Reel | B15: 48656 | C15: 32950 | D15: 127315
A16: Interacciones totales (likes) | B16: 3715 | C16: 3592 | D16: 20104
A17: Engagement rate (rango de entre 3% y 5%) | B17: =B16/B14 | C17: =C16/C14 | D17: =D16/D14
A18: LinkedIn
A19: Total de seguidores | B19: 22094 | C19: 22435 | D19: 23323
A20: Impresiones totales | B20: 93679 | C20: 88915 | D20: 158365
A21: Reacciones totales | B21: 1401 | C21: 1551 | D21: 3196
A22: Engagement rate (rango de entre 3% y 5%) | B22: =B21/B20 | C22: =C21/C20 | D22: =D21/D20
A23: Boletín
A24: Número de suscritos (enviados)
A25: Número de correos entregados
A26: Número de correos abiertos (únicos)
A27: Open rate (número de abiertos únicos / número de entregados) - meta: arriba del 20.39% promedio del sector nonprofits.
A28: Click-Through Rate (CTR) (total único de clicks/total de abiertos únicos) - (CTOR)
A29: TikTok
A30: Número de seguidores | B30: 3324 | C30: 3412 | D30: 3936
A31: Visualizaciones | B31: 26093 | C31: 27600 | D31: 133173
A32: Me gusta | B32: 707 | C32: 920 | D32: 10671
A33: Engagement rate (rango de entre 3% y 5%) | B33: =B32/B31 | C33: =C32/C31 | D33: =D32/D31
A34: Youtube
A35: Suscriptores
A36: Tiempo de reproducción / horas
A37: Vistas/interacción
A38: Youtube
A39: Vistas | B39: 6862 | C39: 15890 | D39: 34785 | E39: 13246
A40: Horas de visualizacion | B40: 130.4 | C40: 128.2 | D40: 385.9 | E40: 128.6
...

Sheet KPIs
A1: Red social | B1: Seguidores actuales | C1: Crecimiento 2025 | D1: Crecimiento 2026 | E1: Nuevos followers / mes (meta) | F1: Seguidores estimados fin de año | G1: Alcance mensual esperado | H1: Alcance anual esperado | I1: Alcance 2025
A2: Facebook | B2: 135044 | C2: 2975 | D2: =F2-B2 | E2: 315 | F2: 138824 | G2: 250000 | H2: =G2*12 | I2: 2462698
A3: Twitter / X | B3: 145071 | C3: -331 | D3: =150*12 | E3: 150 | F3: 148071 | G3: 320000 | H3: =G3*12 | I3: 3211378
A4: Instagram | B4: 14409 | C4: 3105 | D4: =F4-B4 | E4: =+510 | F4: 20529 | G4: 180000 | H4: =G4*12 | I4: 1144520
A5: LinkedIn | B5: 21760 | C5: 4123 | D5: =F5-B5 | E5: 375 | F5: 26260 | G5: 85000 | H5: =G5*12 | I5: 788563
A6: TikTok | B6: 3089 | C6: 447 | D6: =F6-B6 | E6: 250 | F6: 6089 | G6: 50000 | H6: =G6*12 | I6: 339221
A7: Youtube
B9: Facebook | C9: 135044 | D9: 3780
B10: Twitter / X | C10: 145071 | D10: 1800
B11: Instagram | C11: 14409 | D11: 6120
B12: LinkedIn | C12: 21760 | D12: 4500
B13: TikTok | C13: 3089 | D13: 3000
B14: Youtube
B15: Facebook | C15: 138824
B16: Twitter / X | C16: 148071
B17: Instagram | C17: 20529
B18: LinkedIn | C18: 26260
B19: TikTok | C19: 6089
B20: Youtube

Sheet Otros Think Tanks
B1: 20 de enero | C1: 23 de febrero | D1: Diferencia | E1: 30 de marzo | F1: Diferencia | G1: 27 de abril | H1: Diferencia | I1: 25 de mayo | J1: Diferencia | K1: 29 de junio | L1: Diferencia | M1: 27 de julio | N1: Diferencia | O1: 31 de agosto | P1: Diferencia | Q1: 28 de septiembre | R1: Diferencia | S1: 26 de octubre | T1: Diferencia | U1: 30 de noviembre | V1: Diferencia | W1: 21 de diciembre | X1: Diferencia
B2: Twitter
A3: IMCO | B3: 145189 | C3: 145319 | D3: =C3-B3 | E3: 145589 | F3: =E3-C3
A4: México ¿Cómo vamos? | B4: 137242 | C4: 137265 | D4: =C4-B4 | E4: 137201 | F4: =E4-C4
A5: Mexicanos contra la corrupción | B5: 396242 | C5: 397849 | D5: =C5-B5 | E5: 398507 | F5: =E5-C5
A6: México Evalúa | B6: 142996 | C6: 143166 | D6: =C6-B6 | E6: 143186 | F6: =E6-C6
A7: Data Cívica | B7: 33144 | C7: 33179 | D7: =C7-B7 | E7: 33190 | F7: =E7-C7
A8: CIEP | B8: 16530 | C8: 16535 | D8: =C8-B8 | E8: 16525 | F8: =E8-C8
B9: Instagram
A10: IMCO | B10: 14882 | C10: 15486 | D10: =C10-B10 | E10: 17385 | F10: =E10-C10
A11: México ¿Cómo vamos? | B11: 11316 | C11: 11776 | D11: =C11-B11 | E11: 12536 | F11: =E11-C11
A12: Mexicanos contra la corrupción | B12: 33611 | C12: 34108 | D12: =C12-B12 | E12: 34510 | F12: =E12-C12
A13: México Evalúa | B13: 7909 | C13: 7930 | D13: =C13-B13 | E13: 8049 | F13: =E13-C13
A14: Data Cívica | B14: 9032 | C14: 9143 | D14: =C14-B14 | E14: 9659 | F14: =E14-C14
A15: CIEP | B15: 643 | C15: 677 | D15: =C15-B15 | E15: 697 | F15: =E15-C15
B16: LinkedIn
A17: IMCO | B17: 21995 | C17: 22435 | D17: =C17-B17 | E17: 23326 | F17: =E17-C17
A18: México ¿Cómo vamos? | B18: 2718 | C18: 2808 | D18: =C18-B18 | E18: 2981 | F18: =E18-C18
A19: México Evalúa | B19: 14023 | C19: 14245 | D19: =C19-B19 | E19: 14435 | F19: =E19-C19
B20: TikTok
A21: IMCO | B21: 3117 | C21: 3412 | D21: =C21-B21 | E21: 3936 | F21: =E21-C21
A22: México ¿Cómo vamos? | B22: 625 | C22: 689 | D22: =C22-B22 | E22: 729 | F22: =E22-C22
A23: Mexicanos contra la corrupción | B23: 68300 | C23: 68800 | D23: =C23-B23 | E23: 69300 | F23: =E23-C23
A24: México Evalúa | B24: 463 | C24: 473 | D24: =C24-B24 | E24: 489 | F24: =E24-C24

Sheet Seguimiento seguidores
A1: Red social | B1: Seguidores iniciales | C1: Meta mensual (followers) | D1: Ene | E1: Meta | F1: Diferencia | G1: Feb | H1: Meta | I1: Diferencia | J1: Mar | K1: Meta | L1: Diferencia | M1: Abr | N1: Meta | O1: Diferencia | P1: May | Q1: Meta | R1: Diferencia | S1: Jun | T1: Meta | U1: Diferencia | V1: Jul | W1: Meta | X1: Diferencia | Y1: Ago | Z1: Meta | AA1: Diferencia | AB1: Sep | AC1: Meta | AD1: Diferencia | AE1: Oct | AF1: Meta | AG1: Diferencia | AH1: Nov | AI1: Meta | AJ1: Diferencia | AK1: Dic | AL1: Meta | AM1: Diferencia
A2: Facebook | B2: 135044 | C2: 315 | D2: 135863 | E2: =B2+C2 | F2: =D2-E2 | G2: 136255 | H2: =E2+C2 | I2: =G2-H2 | J2: 137734 | K2: =H2+C2 | L2: =J2-K2 | N2: =K2+C2 | O2: =M2-N2 | Q2: =C2+N2 | R2: =P2-Q2 | T2: =C2+Q2 | U2: =S2-T2 | W2: =C2+T2 | X2: =V2-W2 | Z2: =C2+W2 | AA2: =Y2-Z2 | AC2: =C2+Z2 | AD2: =AB2-AC2 | AF2: =C2+AC2 | AG2: =AE2-AF2 | AI2: =C2+AF2 | AJ2: =AH2-AI2 | AL2: =C2+AI2 | AM2: =AK2-AL2
A3: Twitter / X | B3: 145071 | C3: 150 | D3: 145220 | E3: =B3+C3 | F3: =D3-E3 | G3: 145319 | H3: =E3+C3 | I3: =G3-H3 | J3: 145588 | K3: =H3+C3 | L3: =J3-K3 | N3: =K3+C3 | O3: =M3-N3 | Q3: =C3+N3 | R3: =P3-Q3 | T3: =C3+Q3 | U3: =S3-T3 | W3: =C3+T3 | X3: =V3-W3 | Z3: =C3+W3 | AA3: =Y3-Z3 | AC3: =C3+Z3 | AD3: =AB3-AC3 | AF3: =C3+AC3 | AG3: =AE3-AF3 | AI3: =C3+AF3 | AJ3: =AH3-AI3 | AL3: =C3+AI3 | AM3: =AK3-AL3
A4: Instagram | B4: 14409 | C4: =+510 | D4: 15150 | E4: =B4+C4 | F4: =D4-E4 | G4: 15486 | H4: =E4+C4 | I4: =G4-H4 | J4: 17385 | K4: =H4+C4 | L4: =J4-K4 | N4: =K4+C4 | O4: =M4-N4 | Q4: =C4+N4 | R4: =P4-Q4 | T4: =C4+Q4 | U4: =S4-T4 | W4: =C4+T4 | X4: =V4-W4 | Z4: =C4+W4 | AA4: =Y4-Z4 | AC4: =C4+Z4 | AD4: =AB4-AC4 | AF4: =C4+AC4 | AG4: =AE4-AF4 | AI4: =C4+AF4 | AJ4: =AH4-AI4 | AL4: =C4+AI4 | AM4: =AK4-AL4
A5: LinkedIn | B5: 21760 | C5: 375 | D5: 22156 | E5: =B5+C5 | F5: =D5-E5 | G5: 22435 | H5: =E5+C5 | I5: =G5-H5 | J5: 23323 | K5: =H5+C5 | L5: =J5-K5 | N5: =K5+C5 | O5: =M5-N5 | Q5: =C5+N5 | R5: =P5-Q5 | T5: =C5+Q5 | U5: =S5-T5 | W5: =C5+T5 | X5: =V5-W5 | Z5: =C5+W5 | AA5: =Y5-Z5 | AC5: =C5+Z5 | AD5: =AB5-AC5 | AF5: =C5+AC5 | AG5: =AE5-AF5 | AI5: =C5+AF5 | AJ5: =AH5-AI5 | AL5: =C5+AI5 | AM5: =AK5-AL5
A6: TikTok | B6: 3089 | C6: 250 | D6: 3362 | E6: =B6+C6 | F6: =D6-E6 | G6: 3412 | H6: =E6+C6 | I6: =G6-H6 | J6: 3936 | K6: =H6+C6 | L6: =J6-K6 | N6: =K6+C6 | O6: =M6-N6 | Q6: =C6+N6 | R6: =P6-Q6 | T6: =C6+Q6 | U6: =S6-T6 | W6: =C6+T6 | X6: =V6-W6 | Z6: =C6+W6 | AA6: =Y6-Z6 | AC6: =C6+Z6 | AD6: =AB6-AC6 | AF6: =C6+AC6 | AG6: =AE6-AF6 | AI6: =C6+AF6 | AJ6: =AH6-AI6 | AL6: =C6+AI6 | AM6: =AK6-AL6
B9: ACTUAL ENERO 2025 | D9: META FINAL DE AÑO
A10: Facebook | B10: 135044 | C10: Facebook | 3,780 | D10: Facebook | E10: 138824 | F10: =B10+3780
A11: Twitter / X | B11: 145071 | C11: Twitter / X | 1800 | D11: Twitter / X | E11: 146871
A12: Instagram | B12: 14409 | C12: Instagram | 6,120 | D12: Instagram | E12: 20529
A13: LinkedIn | B13: 21760 | C13: LinkedIn | 4,500 | D13: LinkedIn | E13: 26260
A14: TikTok | B14: 3089 | C14: TikTok |3,000 | D14: TikTok | E14: 6089
A15: Facebook | B15: 135359 | C15: Youtube | 6,000
A16: Twitter / X | B16: 145221
A17: Instagram | B17: 14919
A18: LinkedIn | B18: 22135
A19: TikTok | B19: 3339

Sheet Seguimiento alcance
A1: Red social | B1: Meta de alcance mensual | C1: Ene | D1: Ene-2025 | E1: Feb | F1: 45689 | G1: Mar | H1: 45717 | I1: Abr | J1: Abr-2025 | K1: May | L1: 45778 | M1: Jun | N1: 45809 | O1: Jul | P1: 45839 | Q1: Ago | R1: Ago-2025 | S1: Sep | T1: 45901 | U1: Oct | V1: 45931 | W1: Nov | X1: 45962 | Y1: Dic | Z1: Dic-2025
A2: Facebook | B2: 350000 | C2: 591045 | D2: 31407 | E2: 449232 | F2: 40839 | G2: 1072767 | H2: 46793 | J2: 33295 | L2: 65351 | N2: 96098 | P2: 95360 | R2: 398261 | T2: 339404 | V2: 296771 | X2: 638079 | Z2: 381040 | AA2: =sum(D2,F2,H2,J2,L2,N2,P2,R2,T2,V2,X2,Z2)
A3: Twitter / X | B3: 350000 | C3: 333491 | D3: 410335 | E3: 198556 | F3: 301987 | G3: 493938 | H3: 403353 | J3: 257417 | L3: 206040 | N3: 171385 | P3: 225298 | R3: 235204 | T3: 210413 | V3: 213523 | X3: 395282 | Z3: 181141 | AA3: =sum(D3,F3,H3,J3,L3,N3,P3,R3,T3,V3,X3,Z3)
A4: Instagram | B4: 150000 | C4: 122452 | D4: 63926 | E4: 167904 | F4: 62808 | G4: 864800 | H4: 63624 | J4: 14221 | L4: 19804 | N4: 30433 | P4: 22840 | R4: 50961 | T4: 105352 | V4: 129380 | X4: 252115 | Z4: 329056 | AA4: =sum(D4,F4,H4,J4,L4,N4,P4,R4,T4,V4,X4,Z4)
A5: LinkedIn | B5: 85000 | C5: 93679 | D5: 58747 | E5: 88915 | F5: 50763 | G5: 158365 | H5: 73705 | J5: 40965 | L5: 33762 | N5: 57640 | P5: 56713 | R5: 73565 | T5: 75824 | V5: 101416 | X5: 103257 | Z5: 62206 | AA5: =sum(D5,F5,H5,J5,L5,N5,P5,R5,T5,V5,X5,Z5)
A6: TikTok | B6: 45000 | C6: 26093 | D6: 12502 | E6: 27600 | F6: 17871 | G6: 133173 | H6: 98953 | J6: 21284 | L6: 14300 | N6: 25048 | P6: 14467 | R6: 19427 | T6: 15705 | V6: 24666 | X6: 27011 | Z6: 47987 | AA6: =sum(D6,F6,H6,J6,L6,N6,P6,R6,T6,V6,X6,Z6)
B9: Promedio 2025
A10: Facebook | B10: =AVERAGE(D2,F2,H2,J2,L2,N2,P2,R2,T2,V2,X2,Z2)
A11: Twitter / X | B11: =AVERAGE(D3,F3,H3,J3,L3,N3,P3,R3,T3,V3,X3,Z3)
A12: Instagram | B12: =AVERAGE(D4,F4,H4,J4,L4,N4,P4,R4,T4,V4,X4,Z4)
A13: LinkedIn | B13: =AVERAGE(D5,F5,H5,J5,L5,N5,P5,R5,T5,V5,X5,Z5)
A14: TikTok | B14: =AVERAGE(D6,F6,H6,J6,L6,N6,P6,R6,T6,V6,X6,Z6)
A15: Youtube
A17: Red social | B17: Meta 2026
A18: Facebook | B18: 3000000
A19: Twitter / X | B19: 3840000
A20: Instagram | B20: 2160000
A21: LinkedIn | B21: 1020000
A22: TikTok | B22: 600000
